Workbook

Sheet перечень
A1: Номенклатура | B1: Тип упаковки | C1: Толщина, мкм | D1: Длина, м | E1: Ширина, мм | F1: Ø шпули,мм | G1: Масса рулона нетто, кг | H1: Масса рулона брутто, кг | I1: рзамер единицы товара (рулончика) в инд упаковке (ДхШхВ), мм | J1: Намотка м/мин | K1: шт./ в кор. | L1: t намотки рулона, сек | M1: t намотки коробки, сек | N1: шт коробок в мин | O1: шт рулонов в мин. | P1: t укладки в короб, сек | Q1: Размеры корбки(ДхШхВ), мм | R1: масса коробки нетто, кг | S1: масса коробки брутто, кг | T1: коробок/ паллет, шт | U1: рядов в паллете, шт | V1: шт/ряд | W1: масса паллета нетто, кг | X1: масса паллета брутто, кг | Y1: Высота паллеты, мм
A2: MIN значение | C2: =MIN('Перечень '!C2:C281) -> 7 | D2: =MIN('Перечень '!D2:D281) -> 5 | E2: =MIN('Перечень '!E2:E281) -> 280 | F2: =MIN('Перечень '!F2:F281) -> 25 | G2: =MIN('Перечень '!G2:G281) -> 0.0353655 | H2: =MIN('Перечень '!H2:H281) -> 0.0623655 | I2: 305*32*32 | J2: =MIN('Перечень '!J2:J281) -> 200 | K2: =MIN('Перечень '!K2:K281) -> 6 | L2: =MIN('Перечень '!L2:L281) -> 1.5 | M2: =MIN('Перечень '!M2:M281) -> 13.5 | N2: =MIN('Перечень '!N2:N281) -> 0.3030303 | O2: =MIN('Перечень '!O2:O281) -> 2.6666667 | P2: =MIN('Перечень '!P2:P281) -> 15.5 | Q2: По всем видам | R2: =MIN('Перечень '!R2:R281) -> 0.825195 | S2: =MIN('Перечень '!S2:S281) -> 1.430195 | T2: =MIN('Перечень '!T2:T281) -> 28 | U2: =MIN('Перечень '!U2:U281) -> 3 | V2: =MIN('Перечень '!V2:V281) -> 7 | W2: =MIN('Перечень '!W2:W281) -> 191.5718 | X2: =MIN('Перечень '!X2:X281) -> 206.5718 | Y2: 650
A3: MAXзначение | C3: =MAX('Перечень '!C2:C281) -> 30 | D3: =MAX('Перечень '!D2:D281) -> 150 | E3: =MAX('Перечень '!E2:E281) -> 440 | F3: =MAX('Перечень '!F2:F281) -> 33 | G3: =MAX('Перечень '!G2:G281) -> 2.3848 | H3: =MAX('Перечень '!H2:H281) -> 2.4251 | I3: 455*62*62 | J3: =MAX('Перечень '!J2:J281) -> 400 | K3: =MAX('Перечень '!K2:K281) -> 60 | L3: =MAX('Перечень '!L2:L281) -> 22.5 | M3: =MAX('Перечень '!M2:M281) -> 198 | N3: =MAX('Перечень '!N2:N281) -> 4.4444444 | O3: =MAX('Перечень '!O2:O281) -> 40 | P3: =MAX('Перечень '!P2:P281) -> 200 | Q3: По всем видам | R3: =MAX('Перечень '!R2:R281) -> 14.3088 | S3: =MAX('Перечень '!S2:S281) -> 14.7506 | T3: =MAX('Перечень '!T2:T281) -> 220 | U3: =MAX('Перечень '!U2:U281) -> 10 | V3: =MAX('Перечень '!V2:V281) -> 44 | W3: =MAX('Перечень '!W2:W281) -> 886.07794 | X3: =MAX('Перечень '!X2:X281) -> 901.07794 | Y3: 1795
A4: MIN значение | C4: =MIN('Перечень '!C2:C7) -> 7 | D4: =MIN('Перечень '!D2:D7) -> 7 | E4: =MIN('Перечень '!E2:E7) -> 290 | F4: =MIN('Перечень '!F2:F7) -> 25 | G4: =MIN('Перечень '!G2:G7) -> 0.055013 | H4: =MIN('Перечень '!H2:H7) -> 0.082013 | I4: 305*32*32 | J4: =MIN('Перечень '!J2:J7) -> 280 | K4: =MIN('Перечень '!K2:K7) -> 9 | L4: =MIN('Перечень '!L2:L7) -> 1.5 | M4: =MIN('Перечень '!M2:M7) -> 13.5 | N4: =MIN('Перечень '!N2:N7) -> 2.3333333 | O4: =MIN('Перечень '!O2:O7) -> 28 | P4: =MIN('Перечень '!P2:P7) -> 15.5 | Q4: Гофрокороб 314х174х104 | R4: =MIN('Перечень '!R2:R7) -> 0.825195 | S4: =MIN('Перечень '!S2:S7) -> 1.430195 | T4: =MIN('Перечень '!T2:T7) -> 176 | U4: =MIN('Перечень '!U2:U7) -> 4 | V4: =MIN('Перечень '!V2:V7) -> 44 | W4: =MIN('Перечень '!W2:W7) -> 270.14838 | X4: =MIN('Перечень '!X2:X7) -> 285.14838
A5: MAXзначение | C5: =MAX('Перечень '!C2:C7) -> 20 | D5: =MAX('Перечень '!D2:D7) -> 10 | E5: =MAX('Перечень '!E2:E7) -> 290 | F5: =MAX('Перечень '!F2:F7) -> 33 | G5: =MAX('Перечень '!G2:G7) -> 0.15718 | H5: =MAX('Перечень '!H2:H7) -> 0.19548 | I5: 305*41*41 | J5: =MAX('Перечень '!J2:J7) -> 350 | K5: =MAX('Перечень '!K2:K7) -> 15 | L5: =MAX('Перечень '!L2:L7) -> 2.1428571 | M5: =MAX('Перечень '!M2:M7) -> 25.714286 | N5: =MAX('Перечень '!N2:N7) -> 4.4444444 | O5: =MAX('Перечень '!O2:O7) -> 40 | P5: =MAX('Перечень '!P2:P7) -> 27.714286 | Q5: Гофрокороб 314х174х104 | R5: =MAX('Перечень '!R2:R7) -> 1.532505 | S5: =MAX('Перечень '!S2:S7) -> 2.137505 | T5: =MAX('Перечень '!T2:T7) -> 220 | U5: =MAX('Перечень '!U2:U7) -> 5 | V5: =MAX('Перечень '!V2:V7) -> 44 | W5: =MAX('Перечень '!W2:W7) -> 470.2511 | X5: =MAX('Перечень '!X2:X7) -> 485.2511
A6: MIN значение | C6: =MIN('Перечень '!C8:C21) -> 7 | D6: =MIN('Перечень '!D8:D21) -> 10 | E6: =MIN('Перечень '!E8:E21) -> 280 | F6: =MIN('Перечень '!F8:F21) -> 25 | G6: =MIN('Перечень '!G8:G21) -> 0.070731 | H6: =MIN('Перечень '!H8:H21) -> 0.097731 | I6: 305*32*32 | J6: =MIN('Перечень '!J8:J21) -> 350 | K6: =MIN('Перечень '!K8:K21) -> 12 | L6: =MIN('Перечень '!L8:L21) -> 1.7142857 | M6: =MIN('Перечень '!M8:M21) -> 51.428571 | N6: =MIN('Перечень '!N8:N21) -> 0.55555556 | O6: =MIN('Перечень '!O8:O21) -> 6.6666667 | P6: =MIN('Перечень '!P8:P21) -> 53.428571 | Q6: Гофрокороб 195х165х310 | R6: =MIN('Перечень '!R8:R21) -> 2.12193 | S6: =MIN('Перечень '!S8:S21) -> 3.13193 | T6: =MIN('Перечень '!T8:T21) -> 78 | U6: =MIN('Перечень '!U8:U21) -> 3 | V6: =MIN('Перечень '!V8:V21) -> 26 | W6: =MIN('Перечень '!W8:W21) -> 407.1509 | X6: =MIN('Перечень '!X8:X21) -> 422.1509
A7: MAXзначение | C7: =MAX('Перечень '!C8:C21) -> 14 | D7: =MAX('Перечень '!D8:D21) -> 60 | E7: =MAX('Перечень '!E8:E21) -> 290 | F7: =MAX('Перечень '!F8:F21) -> 33 | G7: =MAX('Перечень '!G8:G21) -> 0.518694 | H7: =MAX('Перечень '!H8:H21) -> 0.556994 | I7: 305*50*50 | J7: =MAX('Перечень '!J8:J21) -> 400 | K7: =MAX('Перечень '!K8:K21) -> 30 | L7: =MAX('Перечень '!L8:L21) -> 9 | M7: =MAX('Перечень '!M8:M21) -> 108 | N7: =MAX('Перечень '!N8:N21) -> 1.1666667 | O7: =MAX('Перечень '!O8:O21) -> 35 | P7: =MAX('Перечень '!P8:P21) -> 110 | Q7: Гофрокороб 195х165х310 | R7: =MAX('Перечень '!R8:R21) -> 6.224328 | S7: =MAX('Перечень '!S8:S21) -> 6.883928 | T7: =MAX('Перечень '!T8:T21) -> 130 | U7: =MAX('Перечень '!U8:U21) -> 5 | V7: =MAX('Перечень '!V8:V21) -> 26 | W7: =MAX('Перечень '!W8:W21) -> 816.14812 | X7: =MAX('Перечень '!X8:X21) -> 831.14812
A8: MIN значение | C8: =MIN('Перечень '!C22:C27) -> 7 | D8: =MIN('Перечень '!D22:D27) -> 8 | E8: =MIN('Перечень '!E22:E27) -> 290 | F8: =MIN('Перечень '!F22:F27) -> 25 | G8: =MIN('Перечень '!G22:G27) -> 0.0440104 | H8: =MIN('Перечень '!H22:H27) -> 0.0710104 | I8: 305*32*32 | J8: =MIN('Перечень '!J22:J27) -> 280 | K8: =MIN('Перечень '!K22:K27) -> 20 | L8: =MIN('Перечень '!L22:L27) -> 1.7142857 | M8: =MIN('Перечень '!M22:M27) -> 61.714286 | N8: =MIN('Перечень '!N22:N27) -> 0.66666667 | O8: =MIN('Перечень '!O22:O27) -> 13.333333 | P8: =MIN('Перечень '!P22:P27) -> 63.714286 | Q8: Гофрокороб 210х210х310 | R8: =MIN('Перечень '!R22:R27) -> 1.760416 | S8: =MIN('Перечень '!S22:S27) -> 3.040416 | T8: =MIN('Перечень '!T22:T27) -> 75 | U8: =MIN('Перечень '!U22:U27) -> 5 | V8: =MIN('Перечень '!V22:V27) -> 15 | W8: =MIN('Перечень '!W22:W27) -> 228.0312 | X8: =MIN('Перечень '!X22:X27) -> 243.0312
A9: MAXзначение | C9: =MAX('Перечень '!C22:C27) -> 11 | D9: =MAX('Перечень '!D22:D27) -> 30 | E9: =MAX('Перечень '!E22:E27) -> 290 | F9: =MAX('Перечень '!F22:F27) -> 33 | G9: =MAX('Перечень '!G22:G27) -> 0.212193 | H9: =MAX('Перечень '!H22:H27) -> 0.250493 | I9: 305*45*45 | J9: =MAX('Перечень '!J22:J27) -> 400 | K9: =MAX('Перечень '!K22:K27) -> 40 | L9: =MAX('Перечень '!L22:L27) -> 4.5 | M9: =MAX('Перечень '!M22:M27) -> 90 | N9: =MAX('Перечень '!N22:N27) -> 0.97222222 | O9: =MAX('Перечень '!O22:O27) -> 35 | P9: =MAX('Перечень '!P22:P27) -> 92 | Q9: Гофрокороб 210х210х310 | R9: =MAX('Перечень '!R22:R27) -> 4.24386 | S9: =MAX('Перечень '!S22:S27) -> 5.20986 | T9: =MAX('Перечень '!T22:T27) -> 75 | U9: =MAX('Перечень '!U22:U27) -> 5 | V9: =MAX('Перечень '!V22:V27) -> 15 | W9: =MAX('Перечень '!W22:W27) -> 390.7395 | X9: =MAX('Перечень '!X22:X27) -> 405.7395
A10: MIN значение | C10: =MIN('Перечень '!C28:C31) -> 9 | D10: =MIN('Перечень '!D28:D31) -> 8 | E10: =MIN('Перечень '!E28:E31) -> 290 | F10: =MIN('Перечень '!F28:F31) -> 25 | G10: =MIN('Перечень '!G28:G31) -> 0.0691592 | H10: =MIN('Перечень '!H28:H31) -> 0.0961592 | I10: 305*32*32 | J10: =MIN('Перечень '!J28:J31) -> 280 | K10: =MIN('Перечень '!K28:K31) -> 10 | L10: =MIN('Перечень '!L28:L31) -> 1.7142857 | M10: =MIN('Перечень '!M28:M31) -> 42.857143 | N10: =MIN('Перечень '!N28:N31) -> 0.66666667 | O10: =MIN('Перечень '!O28:O31) -> 6.6666667 | P10: =MIN('Перечень '!P28:P31) -> 44.857143 | Q10: Гофрокороб 324х222х134 | R10: =MIN('Перечень '!R28:R31) -> 1.72898 | S10: =MIN('Перечень '!S28:S31) -> 2.60398 | T10: =MIN('Перечень '!T28:T31) -> 78 | U10: =MIN('Перечень '!U28:U31) -> 3 | V10: =MIN('Перечень '!V28:V31) -> 26 | W10: =MIN('Перечень '!W28:W31) -> 338.5174 | X10: =MIN('Перечень '!X28:X31) -> 353.5174
A11: MAXзначение | C11: =MAX('Перечень '!C28:C31) -> 14 | D11: =MAX('Перечень '!D28:D31) -> 60 | E11: =MAX('Перечень '!E28:E31) -> 290 | F11: =MAX('Перечень '!F28:F31) -> 33 | G11: =MAX('Перечень '!G28:G31) -> 0.424386 | H11: =MAX('Перечень '!H28:H31) -> 0.462686 | I11: 305*50*50 | J11: =MAX('Перечень '!J28:J31) -> 400 | K11: =MAX('Перечень '!K28:K31) -> 25 | L11: =MAX('Перечень '!L28:L31) -> 9 | M11: =MAX('Перечень '!M28:M31) -> 90 | N11: =MAX('Перечень '!N28:N31) -> 1.4 | O11: =MAX('Перечень '!O28:O31) -> 35 | P11: =MAX('Перечень '!P28:P31) -> 92 | Q11: Гофрокороб 324х222х134 | R11: =MAX('Перечень '!R28:R31) -> 5.18694 | S11: =MAX('Перечень '!S28:S31) -> 5.96144 | T11: =MAX('Перечень '!T28:T31) -> 130 | U11: =MAX('Перечень '!U28:U31) -> 5 | V11: =MAX('Перечень '!V28:V31) -> 26 | W11: =MAX('Перечень '!W28:W31) -> 464.99232 | X11: =MAX('Перечень '!X28:X31) -> 479.99232
A12: MIN значение | C12: =MIN('Перечень '!C32:C32) -> 9 | D12: =MIN('Перечень '!D32:D32) -> 12 | E12: =MIN('Перечень '!E32:E32) -> 290 | F12: =MIN('Перечень '!F32:F32) -> 25 | G12: =MIN('Перечень '!G32:G32) -> 0.0848772 | H12: =MIN('Перечень '!H32:H32) -> 0.1118772 | I12: 305*32*32 | J12: =MIN('Перечень '!J32:J32) -> 350 | K12: =MIN('Перечень '!K32:K32) -> 49 | L12: =MIN('Перечень '!L32:L32) -> 2.0571429 | M12: =MIN('Перечень '!M32:M32) -> 100.8 | N12: =MIN('Перечень '!N32:N32) -> 0.5952381 | O12: =MIN('Перечень '!O32:O32) -> 29.166667 | P12: =MIN('Перечень '!P32:P32) -> 102.8 | Q12: Гофрокороб 310х230х210 | R12: =MIN('Перечень '!R32:R32) -> 4.1589828 | S12: =MIN('Перечень '!S32:S32) -> 5.6819828 | T12: =MIN('Перечень '!T32:T32) -> 84 | U12: =MIN('Перечень '!U32:U32) -> 7 | V12: =MIN('Перечень '!V32:V32) -> 12 | W12: =MIN('Перечень '!W32:W32) -> 477.28656 | X12: =MIN('Перечень '!X32:X32) -> 492.28656
A13: MAXзначение | C13: =MAX('Перечень '!C32:C32) -> 9 | D13: =MAX('Перечень '!D32:D32) -> 12 | E13: =MAX('Перечень '!E32:E32) -> 290 | F13: =MAX('Перечень '!F32:F32) -> 25 | G13: =MAX('Перечень '!G32:G32) -> 0.0848772 | H13: =MAX('Перечень '!H32:H32) -> 0.1118772 | I13: 305*32*32 | J13: =MAX('Перечень '!J32:J32) -> 350 | K13: =MAX('Перечень '!K32:K32) -> 49 | L13: =MAX('Перечень '!L32:L32) -> 2.0571429 | M13: =MAX('Перечень '!M32:M32) -> 100.8 | N13: =MAX('Перечень '!N32:N32) -> 0.5952381 | O13: =MAX('Перечень '!O32:O32) -> 29.166667 | P13: =MAX('Перечень '!P32:P32) -> 102.8 | Q13: Гофрокороб 310х230х210 | R13: =MAX('Перечень '!R32:R32) -> 4.1589828 | S13: =MAX('Перечень '!S32:S32) -> 5.6819828 | T13: =MAX('Перечень '!T32:T32) -> 84 | U13: =MAX('Перечень '!U32:U32) -> 7 | V13: =MAX('Перечень '!V32:V32) -> 12 | W13: =MAX('Перечень '!W32:W32) -> 477.28656 | X13: =MAX('Перечень '!X32:X32) -> 492.28656
A14: MIN значение | C14: =MIN('Перечень '!C33:C126) -> 7 | D14: =MIN('Перечень '!D33:D126) -> 6 | E14: =MIN('Перечень '!E33:E126) -> 280 | F14: =MIN('Перечень '!F33:F126) -> 25 | G14: =MIN('Перечень '!G33:G126) -> 0.0518694 | H14: =MIN('Перечень '!H33:H126) -> 0.0788694 | I14: 305*32*32 | J14: =MIN('Перечень '!J33:J126) -> 200 | K14: =MIN('Перечень '!K33:K126) -> 10 | L14: =MIN('Перечень '!L33:L126) -> 1.7142857 | M14: =MIN('Перечень '!M33:M126) -> 30.535714 | N14: =MIN('Перечень '!N33:N126) -> 0.3030303 | O14: =MIN('Перечень '!O33:O126) -> 3.6363636 | P14: =MIN('Перечень '!P33:P126) -> 32.535714 | Q14: Гофрокороб 228х160х310 | R14: =MIN('Перечень '!R33:R126) -> 1.815429 | S14: =MIN('Перечень '!S33:S126) -> 2.960429 | T14: =MIN('Перечень '!T33:T126) -> 72 | U14: =MIN('Перечень '!U33:U126) -> 3 | V14: =MIN('Перечень '!V33:V126) -> 24 | W14: =MIN('Перечень '!W33:W126) -> 284.20118 | X14: =MIN('Перечень '!X33:X126) -> 299.20118
A15: MAXзначение | C15: =MAX('Перечень '!C33:C126) -> 30 | D15: =MAX('Перечень '!D33:D126) -> 110 | E15: =MAX('Перечень '!E33:E126) -> 290 | F15: =MAX('Перечень '!F33:F126) -> 33 | G15: =MAX('Перечень '!G33:G126) -> 1.10026 | H15: =MAX('Перечень '!H33:H126) -> 1.13856 | I15: 305*55*55 | J15: =MAX('Перечень '!J33:J126) -> 400 | K15: =MAX('Перечень '!K33:K126) -> 35 | L15: =MAX('Перечень '!L33:L126) -> 16.5 | M15: =MAX('Перечень '!M33:M126) -> 198 | N15: =MAX('Перечень '!N33:N126) -> 1.9649123 | O15: =MAX('Перечень '!O33:O126) -> 35 | P15: =MAX('Перечень '!P33:P126) -> 200 | Q15: Гофрокороб 228х160х310 | R15: =MAX('Перечень '!R33:R126) -> 11.647038 | S15: =MAX('Перечень '!S33:S126) -> 12.306638 | T15: =MAX('Перечень '!T33:T126) -> 120 | U15: =MAX('Перечень '!U33:U126) -> 5 | V15: =MAX('Перечень '!V33:V126) -> 24 | W15: =MAX('Перечень '!W33:W126) -> 886.07794 | X15: =MAX('Перечень '!X33:X126) -> 901.07794
A16: MIN значение | C16: =MIN('Перечень '!C127:C131) -> 9 | D16: =MIN('Перечень '!D127:D131) -> 7 | E16: =MIN('Перечень '!E127:E131) -> 290 | F16: =MIN('Перечень '!F127:F131) -> 25 | G16: =MIN('Перечень '!G127:G131) -> 0.070731 | H16: =MIN('Перечень '!H127:H131) -> 0.097731 | I16: 305*32*32 | J16: =MIN('Перечень '!J127:J131) -> 280 | K16: =MIN('Перечень '!K127:K131) -> 12 | L16: =MIN('Перечень '!L127:L131) -> 1.5 | M16: =MIN('Перечень '!M127:M131) -> 30 | N16: =MIN('Перечень '!N127:N131) -> 0.53333333 | O16: =MIN('Перечень '!O127:O131) -> 8 | P16: =MIN('Перечень '!P127:P131) -> 32 | Q16: Гофрокороб 310х160х228 | R16: =MIN('Перечень '!R127:R131) -> 1.430338 | S16: =MIN('Перечень '!S127:S131) -> 2.396338 | T16: =MIN('Перечень '!T127:T131) -> 72 | U16: =MIN('Перечень '!U127:U131) -> 3 | V16: =MIN('Перечень '!V127:V131) -> 24 | W16: =MIN('Перечень '!W127:W131) -> 230.04845 | X16: =MIN('Перечень '!X127:X131) -> 245.04845
A17: MAXзначение | C17: =MAX('Перечень '!C127:C131) -> 14 | D17: =MAX('Перечень '!D127:D131) -> 50 | E17: =MAX('Перечень '!E127:E131) -> 290 | F17: =MAX('Перечень '!F127:F131) -> 33 | G17: =MAX('Перечень '!G127:G131) -> 0.510835 | H17: =MAX('Перечень '!H127:H131) -> 0.549135 | I17: 305*47*47 | J17: =MAX('Перечень '!J127:J131) -> 400 | K17: =MAX('Перечень '!K127:K131) -> 35 | L17: =MAX('Перечень '!L127:L131) -> 7.5 | M17: =MAX('Перечень '!M127:M131) -> 112.5 | N17: =MAX('Перечень '!N127:N131) -> 2 | O17: =MAX('Перечень '!O127:O131) -> 40 | P17: =MAX('Перечень '!P127:P131) -> 114.5 | Q17: Гофрокороб 310х160х228 | R17: =MAX('Перечень '!R127:R131) -> 6.13002 | S17: =MAX('Перечень '!S127:S131) -> 6.78962 | T17: =MAX('Перечень '!T127:T131) -> 120 | U17: =MAX('Перечень '!U127:U131) -> 5 | V17: =MAX('Перечень '!V127:V131) -> 24 | W17: =MAX('Перечень '!W127:W131) -> 729.519 | X17: =MAX('Перечень '!X127:X131) -> 744.519
A18: MIN значение | C18: =MIN('Перечень '!C132:C155) -> 7 | D18: =MIN('Перечень '!D132:D155) -> 5 | E18: =MIN('Перечень '!E132:E155) -> 280 | F18: =MIN('Перечень '!F132:F155) -> 25 | G18: =MIN('Перечень '!G132:G155) -> 0.0353655 | H18: =MIN('Перечень '!H132:H155) -> 0.0623655 | I18: 305*32*32 | J18: =MIN('Перечень '!J132:J155) -> 200 | K18: =MIN('Перечень '!K132:K155) -> 24 | L18: =MIN('Перечень '!L132:L155) -> 1.5 | M18: =MIN('Перечень '!M132:M155) -> 41.142857 | N18: =MIN('Перечень '!N132:N155) -> 0.31746032 | O18: =MIN('Перечень '!O132:O155) -> 13.333333 | P18: =MIN('Перечень '!P132:P155) -> 43.142857 | Q18: Гофрокороб 259х193х320 | R18: =MIN('Перечень '!R132:R155) -> 1.697544 | S18: =MIN('Перечень '!S132:S155) -> 3.193544 | T18: =MIN('Перечень '!T132:T155) -> 72 | U18: =MIN('Перечень '!U132:U155) -> 4 | V18: =MIN('Перечень '!V132:V155) -> 18 | W18: =MIN('Перечень '!W132:W155) -> 287.41896 | X18: =MIN('Перечень '!X132:X155) -> 302.41896
A19: MAXзначение | C19: =MAX('Перечень '!C132:C155) -> 30 | D19: =MAX('Перечень '!D132:D155) -> 30 | E19: =MAX('Перечень '!E132:E155) -> 290 | F19: =MAX('Перечень '!F132:F155) -> 33 | G19: =MAX('Перечень '!G132:G155) -> 0.2554175 | H19: =MAX('Перечень '!H132:H155) -> 0.2937175 | I19: 305*45*45 | J19: =MAX('Перечень '!J132:J155) -> 400 | K19: =MAX('Перечень '!K132:K155) -> 48 | L19: =MAX('Перечень '!L132:L155) -> 4.5 | M19: =MAX('Перечень '!M132:M155) -> 189 | N19: =MAX('Перечень '!N132:N155) -> 1.4583333 | O19: =MAX('Перечень '!O132:O155) -> 40 | P19: =MAX('Перечень '!P132:P155) -> 191 | Q19: Гофрокороб 259х193х320 | R19: =MAX('Перечень '!R132:R155) -> 6.931638 | S19: =MAX('Перечень '!S132:S155) -> 8.265638 | T19: =MAX('Перечень '!T132:T155) -> 90 | U19: =MAX('Перечень '!U132:U155) -> 5 | V19: =MAX('Перечень '!V132:V155) -> 18 | W19: =MAX('Перечень '!W132:W155) -> 654.78636 | X19: =MAX('Перечень '!X132:X155) -> 669.78636
A20: MIN значение | C20: =MIN('Перечень '!C156:C158) -> 11 | D20: =MIN('Перечень '!D156:D158) -> 10 | E20: =MIN('Перечень '!E156:E158) -> 290 | F20: =MIN('Перечень '!F156:F158) -> 33 | G20: =MIN('Перечень '!G156:G158) -> 0.086449 | H20: =MIN('Перечень '!H156:H158) -> 0.124749 | I20: 305*41*41 | J20: =MIN('Перечень '!J156:J158) -> 350 | K20: =MIN('Перечень '!K156:K158) -> 28 | L20: =MIN('Перечень '!L156:L158) -> 1.7142857 | M20: =MIN('Перечень '!M156:M158) -> 51.428571 | N20: =MIN('Перечень '!N156:N158) -> 0.71428571 | O20: =MIN('Перечень '!O156:O158) -> 20 | P20: =MIN('Перечень '!P156:P158) -> 53.428571 | Q20: Гофрокороб 320х259х193 | R20: =MIN('Перечень '!R156:R158) -> 2.59347 | S20: =MIN('Перечень '!S156:S158) -> 3.94247 | T20: =MIN('Перечень '!T156:T158) -> 90 | U20: =MIN('Перечень '!U156:U158) -> 5 | V20: =MIN('Перечень '!V156:V158) -> 18 | W20: =MIN('Перечень '!W156:W158) -> 354.8223 | X20: =MIN('Перечень '!X156:X158) -> 369.8223
A21: MAXзначение | C21: =MAX('Перечень '!C156:C158) -> 14 | D21: =MAX('Перечень '!D156:D158) -> 20 | E21: =MAX('Перечень '!E156:E158) -> 290 | F21: =MAX('Перечень '!F156:F158) -> 33 | G21: =MAX('Перечень '!G156:G158) -> 0.172898 | H21: =MAX('Перечень '!H156:H158) -> 0.211198 | I21: 305*41*41 | J21: =MAX('Перечень '!J156:J158) -> 400 | K21: =MAX('Перечень '!K156:K158) -> 30 | L21: =MAX('Перечень '!L156:L158) -> 3 | M21: =MAX('Перечень '!M156:M158) -> 84 | N21: =MAX('Перечень '!N156:N158) -> 1.1666667 | O21: =MAX('Перечень '!O156:O158) -> 35 | P21: =MAX('Перечень '!P156:P158) -> 86 | Q21: Гофрокороб 320х259х193 | R21: =MAX('Перечень '!R156:R158) -> 4.841144 | S21: =MAX('Перечень '!S156:S158) -> 6.113544 | T21: =MAX('Перечень '!T156:T158) -> 90 | U21: =MAX('Перечень '!U156:U158) -> 5 | V21: =MAX('Перечень '!V156:V158) -> 18 | W21: =MAX('Перечень '!W156:W158) -> 550.21896 | X21: =MAX('Перечень '!X156:X158) -> 565.21896
A22: MIN значение | C22: =MIN('Перечень '!C159:C161) -> 9 | D22: =MIN('Перечень '!D159:D161) -> 10 | E22: =MIN('Перечень '!E159:E161) -> 290 | F22: =MIN('Перечень '!F159:F161) -> 33 | G22: =MIN('Перечень '!G159:G161) -> 0.070731 | H22: =MIN('Перечень '!H159:H161) -> 0.109031 | I22: 305*41*41 | J22: =MIN('Перечень '!J159:J161) -> 350 | K22: =MIN('Перечень '!K159:K161) -> 32 | L22: =MIN('Перечень '!L159:L161) -> 1.7142857 | M22: =MIN('Перечень '!M159:M161) -> 54.857143 | N22: =MIN('Перечень '!N159:N161) -> 0.55555556 | O22: =MIN('Перечень '!O159:O161) -> 20 | P22: =MIN('Перечень '!P159:P161) -> 56.857143 | Q22: Гофрокороб 250х250х310 | R22: =MIN('Перечень '!R159:R161) -> 2.263392 | S22: =MIN('Перечень '!S159:S161) -> 3.688992 | T22: =MIN('Перечень '!T159:T161) -> 60 | U22: =MIN('Перечень '!U159:U161) -> 5 | V22: =MIN('Перечень '!V159:V161) -> 12 | W22: =MIN('Перечень '!W159:W161) -> 221.33952 | X22: =MIN('Перечень '!X159:X161) -> 236.33952
A23: MAXзначение | C23: =MAX('Перечень '!C159:C161) -> 20 | D23: =MAX('Перечень '!D159:D161) -> 20 | E23: =MAX('Перечень '!E159:E161) -> 290 | F23: =MAX('Перечень '!F159:F161) -> 33 | G23: =MAX('Перечень '!G159:G161) -> 0.15718 | H23: =MAX('Перечень '!H159:H161) -> 0.19548 | I23: 305*41*41 | J23: =MAX('Перечень '!J159:J161) -> 400 | K23: =MAX('Перечень '!K159:K161) -> 36 | L23: =MAX('Перечень '!L159:L161) -> 3 | M23: =MAX('Перечень '!M159:M161) -> 108 | N23: =MAX('Перечень '!N159:N161) -> 1.09375 | O23: =MAX('Перечень '!O159:O161) -> 35 | P23: =MAX('Перечень '!P159:P161) -> 110 | Q23: Гофрокороб 250х250х310 | R23: =MAX('Перечень '!R159:R161) -> 5.5013 | S23: =MAX('Перечень '!S159:S161) -> 7.0418 | T23: =MAX('Перечень '!T159:T161) -> 60 | U23: =MAX('Перечень '!U159:U161) -> 5 | V23: =MAX('Перечень '!V159:V161) -> 12 | W23: =MAX('Перечень '!W159:W161) -> 422.508 | X23: =MAX('Перечень '!X159:X161) -> 437.508
A24: MIN значение | C24: =MIN('Перечень '!C162:C181) -> 7 | D24: =MIN('Перечень '!D162:D181) -> 5 | E24: =MIN('Перечень '!E162:E181) -> 290 | F24: =MIN('Перечень '!F162:F181) -> 25 | G24: =MIN('Перечень '!G162:G181) -> 0.0353655 | H24: =MIN('Перечень '!H162:H181) -> 0.0623655 | I24: 305*32*32 | J24: =MIN('Перечень '!J162:J181) -> 200 | K24: =MIN('Перечень '!K162:K181) -> 28 | L24: =MIN('Перечень '!L162:L181) -> 1.5 | M24: =MIN('Перечень '!M162:M181) -> 52.5 | N24: =MIN('Перечень '!N162:N181) -> 0.33333333 | O24: =MIN('Перечень '!O162:O181) -> 13.333333 | P24: =MIN('Перечень '!P162:P181) -> 54.5 | Q24: Гофрокороб 320х290х190 | R24: =MIN('Перечень '!R162:R181) -> 1.5128575 | S24: =MIN('Перечень '!S162:S181) -> 3.0533575 | T24: =MIN('Перечень '!T162:T181) -> 64 | U24: =MIN('Перечень '!U162:U181) -> 4 | V24: =MIN('Перечень '!V162:V181) -> 16 | W24: =MIN('Перечень '!W162:W181) -> 244.2686 | X24: =MIN('Перечень '!X162:X181) -> 259.2686
A25: MAXзначение | C25: =MAX('Перечень '!C162:C181) -> 20 | D25: =MAX('Перечень '!D162:D181) -> 30 | E25: =MAX('Перечень '!E162:E181) -> 290 | F25: =MAX('Перечень '!F162:F181) -> 33 | G25: =MAX('Перечень '!G162:G181) -> 0.165039 | H25: =MAX('Перечень '!H162:H181) -> 0.1978377 | I25: 305*45*45 | J25: =MAX('Перечень '!J162:J181) -> 400 | K25: =MAX('Перечень '!K162:K181) -> 54 | L25: =MAX('Перечень '!L162:L181) -> 4.5 | M25: =MAX('Перечень '!M162:M181) -> 180 | N25: =MAX('Перечень '!N162:N181) -> 1.1428571 | O25: =MAX('Перечень '!O162:O181) -> 40 | P25: =MAX('Перечень '!P162:P181) -> 182 | Q25: Гофрокороб 320х290х190 | R25: =MAX('Перечень '!R162:R181) -> 6.60156 | S25: =MAX('Перечень '!S162:S181) -> 7.88156 | T25: =MAX('Перечень '!T162:T181) -> 80 | U25: =MAX('Перечень '!U162:U181) -> 5 | V25: =MAX('Перечень '!V162:V181) -> 16 | W25: =MAX('Перечень '!W162:W181) -> 553.33472 | X25: =MAX('Перечень '!X162:X181) -> 568.33472
A26: MIN значение | C26: =MIN('Перечень '!C182:C182) -> 11 | D26: =MIN('Перечень '!D182:D182) -> 10 | E26: =MIN('Перечень '!E182:E182) -> 290 | F26: =MIN('Перечень '!F182:F182) -> 25 | G26: =MIN('Перечень '!G182:G182) -> 0.086449 | H26: =MIN('Перечень '!H182:H182) -> 0.113449 | I26: 305*32*32 | J26: =MIN('Перечень '!J182:J182) -> 350 | K26: =MIN('Перечень '!K182:K182) -> 60 | L26: =MIN('Перечень '!L182:L182) -> 1.7142857 | M26: =MIN('Перечень '!M182:M182) -> 102.85714 | N26: =MIN('Перечень '!N182:N182) -> 0.58333333 | O26: =MIN('Перечень '!O182:O182) -> 35 | P26: =MIN('Перечень '!P182:P182) -> 104.85714 | Q26: Гофрокороб 395х310х160 | R26: =MIN('Перечень '!R182:R182) -> 5.18694 | S26: =MIN('Перечень '!S182:S182) -> 7.00694 | T26: =MIN('Перечень '!T182:T182) -> 52 | U26: =MIN('Перечень '!U182:U182) -> 4 | V26: =MIN('Перечень '!V182:V182) -> 13 | W26: =MIN('Перечень '!W182:W182) -> 364.36088 | X26: =MIN('Перечень '!X182:X182) -> 379.36088
A27: MAXзначение | C27: =MAX('Перечень '!C182:C182) -> 11 | D27: =MAX('Перечень '!D182:D182) -> 10 | E27: =MAX('Перечень '!E182:E182) -> 290 | F27: =MAX('Перечень '!F182:F182) -> 25 | G27: =MAX('Перечень '!G182:G182) -> 0.086449 | H27: =MAX('Перечень '!H182:H182) -> 0.113449 | I27: 305*32*32 | J27: =MAX('Перечень '!J182:J182) -> 350 | K27: =MAX('Перечень '!K182:K182) -> 60 | L27: =MAX('Перечень '!L182:L182) -> 1.7142857 | M27: =MAX('Перечень '!M182:M182) -> 102.85714 | N27: =MAX('Перечень '!N182:N182) -> 0.58333333 | O27: =MAX('Перечень '!O182:O182) -> 35 | P27: =MAX('Перечень '!P182:P182) -> 104.85714 | Q27: Гофрокороб 395х310х160 | R27: =MAX('Перечень '!R182:R182) -> 5.18694 | S27: =MAX('Перечень '!S182:S182) -> 7.00694 | T27: =MAX('Перечень '!T182:T182) -> 52 | U27: =MAX('Перечень '!U182:U182) -> 4 | V27: =MAX('Перечень '!V182:V182) -> 13 | W27: =MAX('Перечень '!W182:W182) -> 364.36088 | X27: =MAX('Перечень '!X182:X182) -> 379.36088
A28: MIN значение | C28: =MIN('Перечень '!C183:C272) -> 7 | D28: =MIN('Перечень '!D183:D272) -> 7 | E28: =MIN('Перечень '!E183:E272) -> 440 | F28: =MIN('Перечень '!F183:F272) -> 25 | G28: =MIN('Перечень '!G183:G272) -> 0.107316 | H28: =MIN('Перечень '!H183:H272) -> 0.169116 | I28: 305*41*41 | J28: =MIN('Перечень '!J183:J272) -> 280 | K28: =MIN('Перечень '!K183:K272) -> 6 | L28: =MIN('Перечень '!L183:L272) -> 1.5 | M28: =MIN('Перечень '!M183:M272) -> 19.285714 | N28: =MIN('Перечень '!N183:N272) -> 0.44444444 | O28: =MIN('Перечень '!O183:O272) -> 2.6666667 | P28: =MIN('Перечень '!P183:P272) -> 21.285714 | Q28: Гофрокороб 470х222х120 | R28: =MIN('Перечень '!R183:R272) -> 1.60974 | S28: =MIN('Перечень '!S183:S272) -> 2.73674 | T28: =MIN('Перечень '!T183:T272) -> 28 | U28: =MIN('Перечень '!U183:U272) -> 4 | V28: =MIN('Перечень '!V183:V272) -> 7 | W28: =MIN('Перечень '!W183:W272) -> 191.5718 | X28: =MIN('Перечень '!X183:X272) -> 206.5718
A29: MAXзначение | C29: =MAX('Перечень '!C183:C272) -> 30 | D29: =MAX('Перечень '!D183:D272) -> 150 | E29: =MAX('Перечень '!E183:E272) -> 440 | F29: =MAX('Перечень '!F183:F272) -> 33 | G29: =MAX('Перечень '!G183:G272) -> 2.3848 | H29: =MAX('Перечень '!H183:H272) -> 2.4251 | I29: 455*62*62 | J29: =MAX('Перечень '!J183:J272) -> 400 | K29: =MAX('Перечень '!K183:K272) -> 26 | L29: =MAX('Перечень '!L183:L272) -> 22.5 | M29: =MAX('Перечень '!M183:M272) -> 135 | N29: =MAX('Перечень '!N183:N272) -> 3.1111111 | O29: =MAX('Перечень '!O183:O272) -> 40 | P29: =MAX('Перечень '!P183:P272) -> 137 | Q29: Гофрокороб 470х222х120 | R29: =MAX('Перечень '!R183:R272) -> 14.3088 | S29: =MAX('Перечень '!S183:S272) -> 14.7506 | T29: =MAX('Перечень '!T183:T272) -> 70 | U29: =MAX('Перечень '!U183:U272) -> 10 | V29: =MAX('Перечень '!V183:V272) -> 7 | W29: =MAX('Перечень '!W183:W272) -> 676.28736 | X29: =MAX('Перечень '!X183:X272) -> 691.28736
A30: MIN значение | C30: =MIN('Перечень '!C273:C278) -> 7 | D30: =MIN('Перечень '!D273:D278) -> 8 | E30: =MIN('Перечень '!E273:E278) -> 290 | F30: =MIN('Перечень '!F273:F278) -> 25 | G30: =MIN('Перечень '!G273:G278) -> 0.0440104 | H30: =MIN('Перечень '!H273:H278) -> 0.0710104 | I30: 305*32*32 | J30: =MIN('Перечень '!J273:J278) -> 280 | K30: =MIN('Перечень '!K273:K278) -> 7 | L30: =MIN('Перечень '!L273:L278) -> 1.7142857 | M30: =MIN('Перечень '!M273:M278) -> 34.285714 | N30: =MIN('Перечень '!N273:N278) -> 0.81632653 | O30: =MIN('Перечень '!O273:O278) -> 5.7142857 | P30: =MIN('Перечень '!P273:P278) -> 36.285714 | Q30: Гофрокороб 320х135х165 | R30: =MIN('Перечень '!R273:R278) -> 0.880208 | S30: =MIN('Перечень '!S273:S278) -> 1.620208 | T30: =MIN('Перечень '!T273:T278) -> 108 | U30: =MIN('Перечень '!U273:U278) -> 3 | V30: =MIN('Перечень '!V273:V278) -> 36 | W30: =MIN('Перечень '!W273:W278) -> 233.30995 | X30: =MIN('Перечень '!X273:X278) -> 248.30995
A31: MAXзначение | C31: =MAX('Перечень '!C273:C278) -> 11 | D31: =MAX('Перечень '!D273:D278) -> 70 | E31: =MAX('Перечень '!E273:E278) -> 290 | F31: =MAX('Перечень '!F273:F278) -> 33 | G31: =MAX('Перечень '!G273:G278) -> 0.605143 | H31: =MAX('Перечень '!H273:H278) -> 0.643443 | I31: 305*50*50 | J31: =MAX('Перечень '!J273:J278) -> 400 | K31: =MAX('Перечень '!K273:K278) -> 20 | L31: =MAX('Перечень '!L273:L278) -> 10.5 | M31: =MAX('Перечень '!M273:M278) -> 73.5 | N31: =MAX('Перечень '!N273:N278) -> 1.75 | O31: =MAX('Перечень '!O273:O278) -> 35 | P31: =MAX('Перечень '!P273:P278) -> 75.5 | Q31: Гофрокороб 320х135х165 | R31: =MAX('Перечень '!R273:R278) -> 4.236001 | S31: =MAX('Перечень '!S273:S278) -> 4.704101 | T31: =MAX('Перечень '!T273:T278) -> 144 | U31: =MAX('Перечень '!U273:U278) -> 4 | V31: =MAX('Перечень '!V273:V278) -> 36 | W31: =MAX('Перечень '!W273:W278) -> 513.97056 | X31: =MAX('Перечень '!X273:X278) -> 528.97056
A32: MIN значение | C32: =MIN('Перечень '!C279:C281) -> 11 | D32: =MIN('Перечень '!D279:D281) -> 8 | E32: =MIN('Перечень '!E279:E281) -> 440 | F32: =MIN('Перечень '!F279:F281) -> 33 | G32: =MIN('Перечень '!G279:G281) -> 0.1049312 | H32: =MIN('Перечень '!H279:H281) -> 0.1667312 | I32: 455*41*41 | J32: =MIN('Перечень '!J279:J281) -> 280 | K32: =MIN('Перечень '!K279:K281) -> 10 | L32: =MIN('Перечень '!L279:L281) -> 1.7142857 | M32: =MIN('Перечень '!M279:M281) -> 42.857143 | N32: =MIN('Перечень '!N279:N281) -> 0.56737589 | O32: =MIN('Перечень '!O279:O281) -> 5.7142857 | P32: =MIN('Перечень '!P279:P281) -> 44.857143 | Q32: Гофрокороб 470х190х210 | R32: =MIN('Перечень '!R279:R281) -> 2.62328 | S32: =MIN('Перечень '!S279:S281) -> 4.36828 | T32: =MIN('Перечень '!T279:T281) -> 35 | U32: =MIN('Перечень '!U279:U281) -> 5 | V32: =MIN('Перечень '!V279:V281) -> 7 | W32: =MIN('Перечень '!W279:W281) -> 214.04572 | X32: =MIN('Перечень '!X279:X281) -> 229.04572
A33: MAXзначение | C33: =MAX('Перечень '!C279:C281) -> 14 | D33: =MAX('Перечень '!D279:D281) -> 70 | E33: =MAX('Перечень '!E279:E281) -> 440 | F33: =MAX('Перечень '!F279:F281) -> 33 | G33: =MAX('Перечень '!G279:G281) -> 0.918148 | H33: =MAX('Перечень '!H279:H281) -> 0.979948 | I33: 455*50*50 | J33: =MAX('Перечень '!J279:J281) -> 400 | K33: =MAX('Перечень '!K279:K281) -> 25 | L33: =MAX('Перечень '!L279:L281) -> 10.5 | M33: =MAX('Перечень '!M279:M281) -> 105.75 | N33: =MAX('Перечень '!N279:N281) -> 1.4 | O33: =MAX('Перечень '!O279:O281) -> 35 | P33: =MAX('Перечень '!P279:P281) -> 107.75 | Q33: Гофрокороб 470х190х210 | R33: =MAX('Перечень '!R279:R281) -> 10.928346 | S33: =MAX('Перечень '!S279:S281) -> 12.055346 | T33: =MAX('Перечень '!T279:T281) -> 49 | U33: =MAX('Перечень '!U279:U281) -> 7 | V33: =MAX('Перечень '!V279:V281) -> 7 | W33: =MAX('Перечень '!W279:W281) -> 421.93711 | X33: =MAX('Перечень '!X279:X281) -> 436.93711

Sheet Перечень 
A1: Номенклатура | B1: Тип упаковки | C1: Толщина, мкм | D1: Длина, м | E1: Ширина, мм | F1: Ø шпули,мм | G1: Масса рулона нетто, кг | H1: Масса рулона брутто, кг | I1: рзамер единицы товара (рулончика) в инд упаковке (ДхШхВ), мм | J1: Намотка м/мин | K1: шт./ в кор. | L1: t намотки рулона, сек | M1: t намотки коробки, сек | N1: шт коробок в мин | O1: шт рулонов в мин. | P1: t укладки в короб, сек | Q1: Размеры корбки(ДхШхВ), мм | R1: масса коробки нетто, кг | S1: масса коробки брутто, кг | T1: коробок/ паллет, шт | U1: рядов в паллете, шт | V1: шт/ряд | W1: масса паллета нетто, кг | X1: масса паллета брутто, кг | Y1: шт товара/пал
A2: Фольга Саянская Гриль ТНД 10П-290х9 | B2: В пленке | C2: 20 | D2: 10 | E2: 290 | F2: 33 | G2: =IF(C2=14,13*D2*E2*2.71/1000000,C2*D2*E2*2.71/1000000) -> 0.15718 | H2: =IF(AND(E2=290,F2=25),G2+0.026+0.001,IF(AND(E2=290,F2=33),G2+0.037+0.0013,IF(AND(E2=440,F2=33),G2+0.06+0.0018,IF(AND(E2=280,F2=25),G2+0.026+0.001,IF(AND(E2=280,F2=33),G2+0.037+0.0013))))) -> 0.19548 | I2: 305*41*41 | J2: 280 | K2: 9 | L2: =D2*60/J2 -> 2.1428571 | M2: =L2*K2 -> 19.285714 | N2: =K2*60/M2/K2 -> 3.1111111 | O2: =60/L2 -> 28 | P2: =M2+2 -> 21.285714 | Q2: Гофрокороб 314х174х104 Т-23 бел,СПФ | R2: =G2*K2 -> 1.41462 | S2: =(H2*K2)+0.2 -> 1.95932 | T2: 176 | U2: 4 | V2: =T2/U2 -> 44 | W2: =X2-15 -> 344.84032 | X2: =IF(T2=0,0,S2*T2+15) -> 359.84032 | Y2: =T2*K2 -> 1584
A3: Фольга бытовая Командор О10П-290х15 | B3: В пленке | C3: 14 | D3: 10 | E3: 290 | F3: 25 | G3: =IF(C3=14,13*D3*E3*2.71/1000000,C3*D3*E3*2.71/1000000) -> 0.102167 | H3: =IF(AND(E3=290,F3=25),G3+0.026+0.001,IF(AND(E3=290,F3=33),G3+0.037+0.0013,IF(AND(E3=440,F3=33),G3+0.06+0.0018,IF(AND(E3=280,F3=25),G3+0.026+0.001,IF(AND(E3=280,F3=33),G3+0.037+0.0013))))) -> 0.129167 | I3: 305*32*32 | J3: 350 | K3: 15 | L3: =D3*60/J3 -> 1.7142857 | M3: =L3*K3 -> 25.714286 | N3: =K3*60/M3/K3 -> 2.3333333 | O3: =60/L3 -> 35 | P3: =M3+2 -> 27.714286 | Q3: Гофрокороб 314х174х104 Т-23 бел,СПФ | R3: =G3*K3 -> 1.532505 | S3: =(H3*K3)+0.2 -> 2.137505 | T3: 220 | U3: 5 | V3: =T3/U3 -> 44 | W3: =X3-15 -> 470.2511 | X3: =IF(T3=0,0,S3*T3+15) -> 485.2511 | Y3: =T3*K3 -> 3300
A4: Фольга ГРИЛЬ ТНД 7П-290х9 | B4: В пленке | C4: 20 | D4: 7 | E4: 290 | F4: 33 | G4: =IF(C4=14,13*D4*E4*2.71/1000000,C4*D4*E4*2.71/1000000) -> 0.110026 | H4: =IF(AND(E4=290,F4=25),G4+0.026+0.001,IF(AND(E4=290,F4=33),G4+0.037+0.0013,IF(AND(E4=440,F4=33),G4+0.06+0.0018,IF(AND(E4=280,F4=25),G4+0.026+0.001,IF(AND(E4=280,F4=33),G4+0.037+0.0013))))) -> 0.148326 | I4: 305*41*41 | J4: 280 | K4: 9 | L4: =D4*60/J4 -> 1.5 | M4: =L4*K4 -> 13.5 | N4: =K4*60/M4/K4 -> 4.4444444 | O4: =60/L4 -> 40 | P4: =M4+2 -> 15.5 | Q4: Гофрокороб 314х174х104 Т-23 бел,Саянская,СПФ | R4: =G4*K4 -> 0.990234 | S4: =(H4*K4)+0.2 -> 1.534934 | T4: 176 | U4: 4 | V4: =T4/U4 -> 44 | W4: =X4-15 -> 270.14838 | X4: =IF(T4=0,0,S4*T4+15) -> 285.14838 | Y4: =T4*K4 -> 1584
A5: Фольга бытовая Правильное решение С10П-290х15 | B5: В пленке | C5: 9 | D5: 10 | E5: 290 | F5: 25 | G5: =IF(C5=14,13*D5*E5*2.71/1000000,C5*D5*E5*2.71/1000000) -> 0.070731 | H5: =IF(AND(E5=290,F5=25),G5+0.026+0.001,IF(AND(E5=440,F5=25),G5+0.039+0.0013,IF(AND(E5=290,F5=33),G5+0.037+0.0013,IF(AND(E5=440,F5=33),G5+0.06+0.0018,IF(AND(E5=280,F5=25),G5+0.026+0.001,IF(AND(E5=280,F5=33),G5+0.037+0.0013)))))) -> 0.097731 | I5: 305*32*32 | J5: 350 | K5: 15 | L5: =D5*60/J5 -> 1.7142857 | M5: =L5*K5 -> 25.714286 | N5: =K5*60/M5/K5 -> 2.3333333 | O5: =60/L5 -> 35 | P5: =M5+2 -> 27.714286 | Q5: Гофрокороб 314х174х104 Т-23 бел,СПФ | R5: =G5*K5 -> 1.060965 | S5: =(H5*K5)+0.2 -> 1.665965 | T5: 220 | U5: 5 | V5: =T5/U5 -> 44 | W5: =X5-15 -> 366.5123 | X5: =IF(T5=0,0,S5*T5+15) -> 381.5123 | Y5: =T5*K5 -> 3300
A6: Фольга бытовая ОЗОН У10П-290x15 | B6: В пленке | C6: 11 | D6: 10 | E6: 290 | F6: 25 | G6: =IF(C6=14,13*D6*E6*2.71/1000000,C6*D6*E6*2.71/1000000) -> 0.086449 | H6: =IF(AND(E6=290,F6=25),G6+0.026+0.001,IF(AND(E6=440,F6=25),G6+0.039+0.0013,IF(AND(E6=290,F6=33),G6+0.037+0.0013,IF(AND(E6=440,F6=33),G6+0.06+0.0018,IF(AND(E6=280,F6=25),G6+0.026+0.001,IF(AND(E6=280,F6=33),G6+0.037+0.0013)))))) -> 0.113449 | I6: 305*32*32 | J6: 350 | K6: 15 | L6: =D6*60/J6 -> 1.7142857 | M6: =L6*K6 -> 25.714286 | N6: =K6*60/M6/K6 -> 2.3333333 | O6: =60/L6 -> 35 | P6: =M6+2 -> 27.714286 | Q6: Гофрокороб 314х174х104 Т-23 бел,СПФ | R6: =G6*K6 -> 1.296735 | S6: =(H6*K6)+0.2 -> 1.901735 | T6: 220 | U6: 5 | V6: 44 | W6: =X6-15 -> 418.3817 | X6: =IF(T6=0,0,S6*T6+15) -> 433.3817 | Y6: =T6*K6 -> 3300
A7: Фольга бытовая Правильное решение Т10П-290х15 | B7: В пленке | C7: 7 | D7: 10 | E7: 290 | F7: 25 | G7: =IF(C7=14,13*D7*E7*2.71/1000000,C7*D7*E7*2.71/1000000) -> 0.055013 | H7: =IF(AND(E7=290,F7=25),G7+0.026+0.001,IF(AND(E7=440,F7=25),G7+0.039+0.0013,IF(AND(E7=290,F7=33),G7+0.037+0.0013,IF(AND(E7=440,F7=33),G7+0.06+0.0018,IF(AND(E7=280,F7=25),G7+0.026+0.001,IF(AND(E7=280,F7=33),G7+0.037+0.0013)))))) -> 0.082013 | I7: 305*32*32 | J7: 350 | K7: 15 | L7: =D7*60/J7 -> 1.7142857 | M7: =L7*K7 -> 25.714286 | N7: =K7*60/M7/K7 -> 2.3333333 | O7: =60/L7 -> 35 | P7: =M7+2 -> 27.714286 | Q7: Гофрокороб 314х174х104 Т-23 бел,СПФ | R7: =G7*K7 -> 0.825195 | S7: =(H7*K7)+0.2 -> 1.430195 | T7: 220 | U7: 5 | V7: =T7/U7 -> 44 | W7: =X7-15 -> 314.6429 | X7: =IF(T7=0,0,S7*T7+15) -> 329.6429 | Y7: =T7*K7 -> 3300
A8: Фольга бытовая Мадам Повари О10П-290х30 | B8: В пленке | C8: 14 | D8: 10 | E8: 290 | F8: 25 | G8: =IF(C8=14,13*D8*E8*2.71/1000000,C8*D8*E8*2.71/1000000) -> 0.102167 | H8: =IF(AND(E8=290,F8=25),G8+0.026+0.001,IF(AND(E8=290,F8=33),G8+0.037+0.0013,IF(AND(E8=440,F8=33),G8+0.06+0.0018,IF(AND(E8=280,F8=25),G8+0.026+0.001,IF(AND(E8=280,F8=33),G8+0.037+0.0013))))) -> 0.129167 | I8: 305*32*32 | J8: 350 | K8: 30 | L8: =D8*60/J8 -> 1.7142857 | M8: =L8*K8 -> 51.428571 | N8: =K8*60/M8/K8 -> 1.1666667 | O8: =60/L8 -> 35 | P8: =M8+2 -> 53.428571 | Q8: Гофрокороб 195х165х310 Т-23 бур,БПФ | R8: =G8*K8 -> 3.06501 | S8: =(H8*K8)+0.2 -> 4.07501 | T8: 130 | U8: =T8/V8 -> 5 | V8: 26 | W8: =X8-15 -> 529.7513 | X8: =IF(T8=0,0,S8*T8+15) -> 544.7513 | Y8: =T8*K8 -> 3900
A9: Фольга бытовая Мадам Повари С10П-290х30 | B9: В пленке | C9: 9 | D9: 10 | E9: 290 | F9: 25 | G9: =IF(C9=14,13*D9*E9*2.71/1000000,C9*D9*E9*2.71/1000000) -> 0.070731 | H9: =IF(AND(E9=290,F9=25),G9+0.026+0.001,IF(AND(E9=290,F9=33),G9+0.037+0.0013,IF(AND(E9=440,F9=33),G9+0.06+0.0018,IF(AND(E9=280,F9=25),G9+0.026+0.001,IF(AND(E9=280,F9=33),G9+0.037+0.0013))))) -> 0.097731 | I9: 305*32*32 | J9: 350 | K9: 30 | L9: =D9*60/J9 -> 1.7142857 | M9: =L9*K9 -> 51.428571 | N9: =K9*60/M9/K9 -> 1.1666667 | O9: =60/L9 -> 35 | P9: =M9+2 -> 53.428571 | Q9: Гофрокороб 195х165х310 Т-23 бур,БПФ | R9: =G9*K9 -> 2.12193 | S9: =(H9*K9)+0.2 -> 3.13193 | T9: 130 | U9: =T9/V9 -> 5 | V9: 26 | W9: =X9-15 -> 407.1509 | X9: =IF(T9=0,0,S9*T9+15) -> 422.1509 | Y9: =T9*K9 -> 3900
A10: Фольга бытовая Мадам Повари У10П-290х30 | B10: В пленке | C10: 11 | D10: 10 | E10: 290 | F10: 25 | G10: =IF(C10=14,13*D10*E10*2.71/1000000,C10*D10*E10*2.71/1000000) -> 0.086449 | H10: =IF(AND(E10=290,F10=25),G10+0.026+0.001,IF(AND(E10=290,F10=33),G10+0.037+0.0013,IF(AND(E10=440,F10=33),G10+0.06+0.0018,IF(AND(E10=280,F10=25),G10+0.026+0.001,IF(AND(E10=280,F10=33),G10+0.037+0.0013))))) -> 0.113449 | I10: 305*32*32 | J10: 350 | K10: 30 | L10: =D10*60/J10 -> 1.7142857 | M10: =L10*K10 -> 51.428571 | N10: =K10*60/M10/K10 -> 1.1666667 | O10: =60/L10 -> 35 | P10: =M10+2 -> 53.428571 | Q10: Гофрокороб 195х165х310 Т-23 бур,БПФ | R10: =G10*K10 -> 2.59347 | S10: =(H10*K10)+0.2 -> 3.60347 | T10: 130 | U10: =T10/V10 -> 5 | V10: 26 | W10: =X10-15 -> 468.4511 | X10: =IF(T10=0,0,S10*T10+15) -> 483.4511 | Y10: =T10*K10 -> 3900
A11: Фольга бытовая Мадам Повари У20П-290х25 | B11: В пленке | C11: 11 | D11: 20 | E11: 290 | F11: 25 | G11: =IF(C11=14,13*D11*E11*2.71/1000000,C11*D11*E11*2.71/1000000) -> 0.172898 | H11: =IF(AND(E11=290,F11=25),G11+0.026+0.001,IF(AND(E11=290,F11=33),G11+0.037+0.0013,IF(AND(E11=440,F11=33),G11+0.06+0.0018,IF(AND(E11=280,F11=25),G11+0.026+0.001,IF(AND(E11=280,F11=33),G11+0.037+0.0013))))) -> 0.199898 | I11: 305*35*35 | J11: 400 | K11: 25 | L11: =D11*60/J11 -> 3 | M11: =L11*K11 -> 75 | N11: =K11*60/M11/K11 -> 0.8 | O11: =60/L11 -> 20 | P11: =M11+2 -> 77 | Q11: Гофрокороб 195х165х310 Т-23 бур,БПФ | R11: =G11*K11 -> 4.32245 | S11: =(H11*K11)+0.2 -> 5.19745 | T11: 130 | U11: =T11/V11 -> 5 | V11: 26 | W11: =X11-15 -> 675.6685 | X11: =IF(T11=0,0,S11*T11+15) -> 690.6685 | Y11: =T11*K11 -> 3250
A12: Фольга бытовая PARLO С15П-290х30 | B12: В пленке | C12: 7 | D12: 15 | E12: 290 | F12: 25 | G12: =IF(C12=14,13*D12*E12*2.71/1000000,C12*D12*E12*2.71/1000000) -> 0.0825195 | H12: =IF(AND(E12=290,F12=25),G12+0.026+0.001,IF(AND(E12=290,F12=33),G12+0.037+0.0013,IF(AND(E12=440,F12=33),G12+0.06+0.0018,IF(AND(E12=280,F12=25),G12+0.026+0.001,IF(AND(E12=280,F12=33),G12+0.037+0.0013))))) -> 0.1095195 | I12: 305*32*32 | J12: 350 | K12: 30 | L12: =D12*60/J12 -> 2.5714286 | M12: =L12*K12 -> 77.142857 | N12: =K12*60/M12/K12 -> 0.77777778 | O12: =60/L12 -> 23.333333 | P12: =M12+2 -> 79.142857 | Q12: Гофрокороб 195х165х310 Т-23 бур,БПФ | R12: =G12*K12 -> 2.475585 | S12: =(H12*K12)+0.2 -> 3.485585 | T12: 130 | U12: 5 | V12: =T12/U12 -> 26 | W12: =X12-15 -> 453.12605 | X12: =IF(T12=0,0,S12*T12+15) -> 468.12605 | Y12: =T12*K12 -> 3900
A13: Фольга Саяночка С50П-290х12 | B13: В пленке | C13: 9 | D13: 50 | E13: 290 | F13: 33 | G13: =IF(C13=14,13*D13*E13*2.71/1000000,C13*D13*E13*2.71/1000000) -> 0.353655 | H13: =IF(AND(E13=290,F13=25),G13+0.026+0.001,IF(AND(E13=290,F13=33),G13+0.037+0.0013,IF(AND(E13=440,F13=33),G13+0.06+0.0018,IF(AND(E13=280,F13=25),G13+0.026+0.001,IF(AND(E13=280,F13=33),G13+0.037+0.0013))))) -> 0.391955 | I13: 305*47*47 | J13: 400 | K13: 12 | L13: =D13*60/J13 -> 7.5 | M13: =L13*K13 -> 90 | N13: =K13*60/M13/K13 -> 0.66666667 | O13: =60/L13 -> 8 | P13: =M13+2 -> 92 | Q13: Гофрокороб 195х165х310 Т-23 бур,БПФ | R13: =G13*K13 -> 4.24386 | S13: =(H13*K13)+0.2 -> 4.90346 | T13: 104 | U13: 4 | V13: =T13/U13 -> 26 | W13: =X13-15 -> 509.95984 | X13: =IF(T13=0,0,S13*T13+15) -> 524.95984 | Y13: =T13*K13 -> 1248
A14: Фольга бытовая ЛЕНТА У25П-290х25 | B14: В пленке | C14: 11 | D14: 25 | E14: 290 | F14: 25 | G14: =IF(C14=14,13*D14*E14*2.71/1000000,C14*D14*E14*2.71/1000000) -> 0.2161225 | H14: =IF(AND(E14=290,F14=25),G14+0.026+0.001,IF(AND(E14=290,F14=33),G14+0.037+0.0013,IF(AND(E14=440,F14=33),G14+0.06+0.0018,IF(AND(E14=280,F14=25),G14+0.026+0.001,IF(AND(E14=280,F14=33),G14+0.037+0.0013))))) -> 0.2431225 | I14: 305*35*35 | J14: 400 | K14: 25 | L14: =D14*60/J14 -> 3.75 | M14: =L14*K14 -> 93.75 | N14: =K14*60/M14/K14 -> 0.64 | O14: =60/L14 -> 16 | P14: =M14+2 -> 95.75 | Q14: Гофрокороб 195х165х310 Т-23 бур,БПФ | R14: =G14*K14 -> 5.4030625 | S14: =(H14*K14)+0.2 -> 6.2780625 | T14: 130 | U14: =T14/V14 -> 5 | V14: 26 | W14: =X14-15 -> 816.14812 | X14: =IF(T14=0,0,S14*T14+15) -> 831.14812 | Y14: =T14*K14 -> 3250
A15: Фольга бытовая С60-280х12 б/у | B15: Без упаковки | C15: 9 | D15: 60 | E15: 280 | F15: 33 | G15: =IF(C15=14,13*D15*E15*2.71/1000000,C15*D15*E15*2.71/1000000) -> 0.409752 | H15: =IF(AND(E15=290,F15=25),G15+0.026+0.001,IF(AND(E15=290,F15=33),G15+0.037+0.0013,IF(AND(E15=440,F15=33),G15+0.06+0.0018,IF(AND(E15=280,F15=25),G15+0.026+0.001,IF(AND(E15=280,F15=33),G15+0.037+0.0013))))) -> 0.448052 | I15: 305*50*50 | J15: 400 | K15: 12 | L15: =D15*60/J15 -> 9 | M15: =L15*K15 -> 108 | N15: =K15*60/M15/K15 -> 0.55555556 | O15: =60/L15 -> 6.6666667 | P15: =M15+2 -> 110 | Q15: Гофрокороб 195х165х310 Т-23 бур,БПФ | R15: =G15*K15 -> 4.917024 | S15: =(H15*K15)+0.2 -> 5.576624 | T15: 78 | U15: 3 | V15: =T15/U15 -> 26 | W15: =X15-15 -> 434.97667 | X15: =IF(T15=0,0,S15*T15+15) -> 449.97667 | Y15: =T15*K15 -> 936
A16: Фольга бытовая С48П - 290х15 упак б/печ. | B16: В пленке | C16: 9 | D16: 48 | E16: 290 | F16: 33 | G16: =IF(C16=14,13*D16*E16*2.71/1000000,C16*D16*E16*2.71/1000000) -> 0.3395088 | H16: =IF(AND(E16=290,F16=25),G16+0.026+0.001,IF(AND(E16=290,F16=33),G16+0.037+0.0013,IF(AND(E16=440,F16=33),G16+0.06+0.0018,IF(AND(E16=280,F16=25),G16+0.026+0.001,IF(AND(E16=280,F16=33),G16+0.037+0.0013))))) -> 0.3778088 | I16: 305*47*47 | J16: 400 | K16: 15 | L16: =D16*60/J16 -> 7.2 | M16: =L16*K16 -> 108 | N16: =K16*60/M16/K16 -> 0.55555556 | O16: =60/L16 -> 8.3333333 | P16: =M16+2 -> 110 | Q16: Гофрокороб 195х165х310 Т-23 бур,БПФ | R16: =G16*K16 -> 5.092632 | S16: =(H16*K16)+0.2 -> 5.867132 | T16: 78 | U16: 3 | V16: =T16/U16 -> 26 | W16: =X16-15 -> 457.6363 | X16: =IF(T16=0,0,S16*T16+15) -> 472.6363 | Y16: =T16*K16 -> 1170
A17: Фольга бытовая У60-290 х12 б/у | B17: Без упаковки | C17: 11 | D17: 60 | E17: 290 | F17: 33 | G17: =IF(C17=14,13*D17*E17*2.71/1000000,C17*D17*E17*2.71/1000000) -> 0.518694 | H17: =IF(AND(E17=290,F17=25),G17+0.026+0.001,IF(AND(E17=290,F17=33),G17+0.037+0.0013,IF(AND(E17=440,F17=33),G17+0.06+0.0018,IF(AND(E17=280,F17=25),G17+0.026+0.001,IF(AND(E17=280,F17=33),G17+0.037+0.0013))))) -> 0.556994 | I17: 305*50*50 | J17: 400 | K17: 12 | L17: =D17*60/J17 -> 9 | M17: =L17*K17 -> 108 | N17: =K17*60/M17/K17 -> 0.55555556 | O17: =60/L17 -> 6.6666667 | P17: =M17+2 -> 110 | Q17: Гофрокороб 195х165х310 Т-23 бур БПФ | R17: =G17*K17 -> 6.224328 | S17: =(H17*K17)+0.2 -> 6.883928 | T17: 78 | U17: 3 | V17: =T17/U17 -> 26 | W17: =X17-15 -> 536.94638 | X17: =IF(T17=0,0,S17*T17+15) -> 551.94638 | Y17: =T17*K17 -> 936
A18: Фольга бытовая О30П-290х15 упак б/печ. | B18: В пленке | C18: 14 | D18: 30 | E18: 290 | F18: 33 | G18: =IF(C18=14,13*D18*E18*2.71/1000000,C18*D18*E18*2.71/1000000) -> 0.306501 | H18: =IF(AND(E18=290,F18=25),G18+0.026+0.001,IF(AND(E18=290,F18=33),G18+0.037+0.0013,IF(AND(E18=440,F18=33),G18+0.06+0.0018,IF(AND(E18=280,F18=25),G18+0.026+0.001,IF(AND(E18=280,F18=33),G18+0.037+0.0013))))) -> 0.344801 | I18: 305*45*45 | J18: 400 | K18: 15 | L18: =D18*60/J18 -> 4.5 | M18: =L18*K18 -> 67.5 | N18: =K18*60/M18/K18 -> 0.88888889 | O18: =60/L18 -> 13.333333 | P18: =M18+2 -> 69.5 | Q18: Гофрокороб 195х165х310 Т-23 бур,БПФ | R18: =G18*K18 -> 4.597515 | S18: =(H18*K18)+0.2 -> 5.372015 | T18: 78 | U18: 3 | V18: =T18/U18 -> 26 | W18: =X18-15 -> 419.01717 | X18: =IF(T18=0,0,S18*T18+15) -> 434.01717 | Y18: =T18*K18 -> 1170
A19: Фольга бытовая О33П-290х15 упак б/печ. | B19: В пленке | C19: 14 | D19: 33 | E19: 290 | F19: 33 | G19: =IF(C19=14,13*D19*E19*2.71/1000000,C19*D19*E19*2.71/1000000) -> 0.3371511 | H19: =IF(AND(E19=290,F19=25),G19+0.026+0.001,IF(AND(E19=290,F19=33),G19+0.037+0.0013,IF(AND(E19=440,F19=33),G19+0.06+0.0018,IF(AND(E19=280,F19=25),G19+0.026+0.001,IF(AND(E19=280,F19=33),G19+0.037+0.0013))))) -> 0.3754511 | I19: 305*45*45 | J19: 400 | K19: 15 | L19: =D19*60/J19 -> 4.95 | M19: =L19*K19 -> 74.25 | N19: =K19*60/M19/K19 -> 0.80808081 | O19: =60/L19 -> 12.121212 | P19: =M19+2 -> 76.25 | Q19: Гофрокороб 195х165х310 Т-23 бур,БПФ | R19: =G19*K19 -> 5.0572665 | S19: =(H19*K19)+0.2 -> 5.8317665 | T19: 78 | U19: 3 | V19: =T19/U19 -> 26 | W19: =X19-15 -> 454.87779 | X19: =IF(T19=0,0,S19*T19+15) -> 469.87779 | Y19: =T19*K19 -> 1170
A20: Фольга бытовая О35П-290х15 упак б/печ | B20: В пленке | C20: 14 | D20: 35 | E20: 290 | F20: 33 | G20: =C20*D20*E20*2.71/1000000 -> 0.385091 | H20: =IF(AND(E20=290,F20=25),G20+0.026+0.001,IF(AND(E20=290,F20=33),G20+0.037+0.0013,IF(AND(E20=440,F20=33),G20+0.06+0.0018,IF(AND(E20=280,F20=25),G20+0.026+0.001,IF(AND(E20=280,F20=33),G20+0.037+0.0013))))) -> 0.423391 | I20: 305*45*45 | J20: 400 | K20: 15 | L20: =D20*60/J20 -> 5.25 | M20: =L20*K20 -> 78.75 | N20: =K20*60/M20/K20 -> 0.76190476 | O20: =60/L20 -> 11.428571 | P20: =M20+2 -> 80.75 | Q20: Гофрокороб 195х165х310 Т-23 бур,БПФ | R20: =G20*K20 -> 5.776365 | S20: =(H20*K20)+0.2 -> 6.550865 | T20: 78 | U20: 3 | V20: =T20/U20 -> 26 | W20: =X20-15 -> 510.96747 | X20: =IF(T20=0,0,S20*T20+15) -> 525.96747 | Y20: =T20*K20 -> 1170
A21: Фольга У56П-290х12 упак б/п | B21: В пленке | C21: 11 | D21: 56 | E21: 290 | F21: 33 | G21: =C21*D21*E21*2.71/1000000 -> 0.4841144 | H21: =IF(AND(E21=290,F21=25),G21+0.026+0.001,IF(AND(E21=290,F21=33),G21+0.037+0.0013,IF(AND(E21=440,F21=33),G21+0.06+0.0018,IF(AND(E21=280,F21=25),G21+0.026+0.001,IF(AND(E21=280,F21=33),G21+0.037+0.0013))))) -> 0.5224144 | I21: 305*50*50 | J21: 400 | K21: 12 | L21: =D21*60/J21 -> 8.4 | M21: =L21*K21 -> 100.8 | N21: =K21*60/M21/K21 -> 0.5952381 | O21: =60/L21 -> 7.1428571 | P21: =M21+2 -> 102.8 | Q21: Гофрокороб 195х165х310 Т-23 бур,БПФ | R21: =G21*K21 -> 5.8093728 | S21: =(H21*K21)+0.2 -> 6.4689728 | T21: 78 | U21: 3 | V21: =T21/U21 -> 26 | W21: =X21-15 -> 504.57988 | X21: =IF(T21=0,0,S21*T21+15) -> 519.57988 | Y21: =T21*K21 -> 936
A22: Фольга PACLAN С30П-290х20 | B22: В пленке | C22: 9 | D22: 30 | E22: 290 | F22: 33 | G22: =IF(C22=14,13*D22*E22*2.71/1000000,C22*D22*E22*2.71/1000000) -> 0.212193 | H22: =IF(AND(E22=290,F22=25),G22+0.026+0.001,IF(AND(E22=290,F22=33),G22+0.037+0.0013,IF(AND(E22=440,F22=33),G22+0.06+0.0018,IF(AND(E22=280,F22=25),G22+0.026+0.001,IF(AND(E22=280,F22=33),G22+0.037+0.0013))))) -> 0.250493 | I22: 305*45*45 | J22: 400 | K22: 20 | L22: =D22*60/J22 -> 4.5 | M22: =L22*K22 -> 90 | N22: =K22*60/M22/K22 -> 0.66666667 | O22: =60/L22 -> 13.333333 | P22: =M22+2 -> 92 | Q22: Гофрокороб 210х210х310 Т-23 черн,Paclan,СПФ | R22: =G22*K22 -> 4.24386 | S22: =(H22*K22)+0.2 -> 5.20986 | T22: 75 | U22: 5 | V22: =T22/U22 -> 15 | W22: =X22-15 -> 390.7395 | X22: =IF(T22=0,0,S22*T22+15) -> 405.7395 | Y22: =T22*K22 -> 1500
A23: Фольга бытовая Master FRESH C10П-290х40 | B23: В пленке | C23: 9 | D23: 10 | E23: 290 | F23: 25 | G23: =IF(C23=14,13*D23*E23*2.71/1000000,C23*D23*E23*2.71/1000000) -> 0.070731 | H23: =IF(AND(E23=290,F23=25),G23+0.026+0.001,IF(AND(E23=290,F23=33),G23+0.037+0.0013,IF(AND(E23=440,F23=33),G23+0.06+0.0018,IF(AND(E23=280,F23=25),G23+0.026+0.001,IF(AND(E23=280,F23=33),G23+0.037+0.0013))))) -> 0.097731 | I23: 305*32*32 | J23: 350 | K23: 40 | L23: =D23*60/J23 -> 1.7142857 | M23: =L23*K23 -> 68.571429 | N23: =K23*60/M23/K23 -> 0.875 | O23: =60/L23 -> 35 | P23: =M23+2 -> 70.571429 | Q23: Гофрокороб 210х210х310 Т-23 бур,БПФ | R23: =G23*K23 -> 2.82924 | S23: =(H23*K23)+0.2 -> 4.10924 | T23: 75 | U23: 5 | V23: =T23/U23 -> 15 | W23: =X23-15 -> 308.193 | X23: =IF(T23=0,0,S23*T23+15) -> 323.193 | Y23: =T23*K23 -> 3000
A24: Фольга бытовая Master FRESH У10П-290х40 | B24: В пленке | C24: 11 | D24: 10 | E24: 290 | F24: 25 | G24: =IF(C24=14,13*D24*E24*2.71/1000000,C24*D24*E24*2.71/1000000) -> 0.086449 | H24: =IF(AND(E24=290,F24=25),G24+0.026+0.001,IF(AND(E24=290,F24=33),G24+0.037+0.0013,IF(AND(E24=440,F24=33),G24+0.06+0.0018,IF(AND(E24=280,F24=25),G24+0.026+0.001,IF(AND(E24=280,F24=33),G24+0.037+0.0013))))) -> 0.113449 | I24: 305*32*32 | J24: 350 | K24: 40 | L24: =D24*60/J24 -> 1.7142857 | M24: =L24*K24 -> 68.571429 | N24: =K24*60/M24/K24 -> 0.875 | O24: =60/L24 -> 35 | P24: =M24+2 -> 70.571429 | Q24: Гофрокороб 210х210х310 Т-23 бур,БПФ | R24: =G24*K24 -> 3.45796 | S24: =(H24*K24)+0.2 -> 4.73796 | T24: 75 | U24: 5 | V24: =T24/U24 -> 15 | W24: =X24-15 -> 355.347 | X24: =IF(T24=0,0,S24*T24+15) -> 370.347 | Y24: =T24*K24 -> 3000
A25: Фольга бытовая PARLO C8П-290х40 (7 мкм) | B25: В пленке | C25: 7 | D25: 8 | E25: 290 | F25: 25 | G25: =IF(C25=14,13*D25*E25*2.71/1000000,C25*D25*E25*2.71/1000000) -> 0.0440104 | H25: =IF(AND(E25=290,F25=25),G25+0.026+0.001,IF(AND(E25=290,F25=33),G25+0.037+0.0013,IF(AND(E25=440,F25=33),G25+0.06+0.0018,IF(AND(E25=280,F25=25),G25+0.026+0.001,IF(AND(E25=280,F25=33),G25+0.037+0.0013))))) -> 0.0710104 | I25: 305*32*32 | J25: 280 | K25: 40 | L25: =D25*60/J25 -> 1.7142857 | M25: =L25*K25 -> 68.571429 | N25: =K25*60/M25/K25 -> 0.875 | O25: =60/L25 -> 35 | P25: =M25+2 -> 70.571429 | Q25: Гофрокороб 210х210х310 Т-23 бур,БПФ | R25: =G25*K25 -> 1.760416 | S25: =(H25*K25)+0.2 -> 3.040416 | T25: 75 | U25: 5 | V25: =T25/U25 -> 15 | W25: =X25-15 -> 228.0312 | X25: =IF(T25=0,0,S25*T25+15) -> 243.0312 | Y25: =T25*K25 -> 3000
A26: Фольга бытовая PARLO C8П-290х40 (9 мкм) | B26: В пленке | C26: 9 | D26: 8 | E26: 290 | F26: 25 | G26: =IF(C26=14,13*D26*E26*2.71/1000000,C26*D26*E26*2.71/1000000) -> 0.0565848 | H26: =IF(AND(E26=290,F26=25),G26+0.026+0.001,IF(AND(E26=290,F26=33),G26+0.037+0.0013,IF(AND(E26=440,F26=33),G26+0.06+0.0018,IF(AND(E26=280,F26=25),G26+0.026+0.001,IF(AND(E26=280,F26=33),G26+0.037+0.0013))))) -> 0.0835848 | I26: 305*32*32 | J26: 280 | K26: 40 | L26: =D26*60/J26 -> 1.7142857 | M26: =L26*K26 -> 68.571429 | N26: =K26*60/M26/K26 -> 0.875 | O26: =60/L26 -> 35 | P26: =M26+2 -> 70.571429 | Q26: Гофрокороб 210х210х310 Т-23 бур,БПФ | R26: =G26*K26 -> 2.263392 | S26: =(H26*K26)+0.2 -> 3.543392 | T26: 75 | U26: 5 | V26: =T26/U26 -> 15 | W26: =X26-15 -> 265.7544 | X26: =IF(T26=0,0,S26*T26+15) -> 280.7544 | Y26: =T26*K26 -> 3000
A27: Фольга DANKE У10Пх36 | B27: В пленке | C27: 11 | D27: 10 | E27: 290 | F27: 25 | G27: =IF(C27=14,13*D27*E27*2.71/1000000,C27*D27*E27*2.71/1000000) -> 0.086449 | H27: =IF(AND(E27=290,F27=25),G27+0.026+0.001,IF(AND(E27=290,F27=33),G27+0.037+0.0013,IF(AND(E27=440,F27=33),G27+0.06+0.0018,IF(AND(E27=280,F27=25),G27+0.026+0.001,IF(AND(E27=280,F27=33),G27+0.037+0.0013))))) -> 0.113449 | I27: 305*32*32 | J27: 350 | K27: 36 | L27: =D27*60/J27 -> 1.7142857 | M27: =L27*K27 -> 61.714286 | N27: =K27*60/M27/K27 -> 0.97222222 | O27: =60/L27 -> 35 | P27: =M27+2 -> 63.714286 | Q27: Гофрокороб 210х210х310 Т-23 бел,СПФ | R27: =G27*K27 -> 3.112164 | S27: =(H27*K27)+0.2 -> 4.284164 | T27: 75 | U27: 5 | V27: =T27/U27 -> 15 | W27: =X27-15 -> 321.3123 | X27: =IF(T27=0,0,S27*T27+15) -> 336.3123 | Y27: =T27*K27 -> 2700
A28: Фольга Классическая У40П-290х15 | B28: В пленке | C28: 11 | D28: 40 | E28: 290 | F28: 33 | G28: =IF(C28=14,13*D28*E28*2.71/1000000,C28*D28*E28*2.71/1000000) -> 0.345796 | H28: =IF(AND(E28=290,F28=25),G28+0.026+0.001,IF(AND(E28=290,F28=33),G28+0.037+0.0013,IF(AND(E28=440,F28=33),G28+0.06+0.0018,IF(AND(E28=280,F28=25),G28+0.026+0.001,IF(AND(E28=280,F28=33),G28+0.037+0.0013))))) -> 0.384096 | I28: 305*45*45 | J28: 400 | K28: 15 | L28: =D28*60/J28 -> 6 | M28: =L28*K28 -> 90 | N28: =K28*60/M28/K28 -> 0.66666667 | O28: =60/L28 -> 10 | P28: =M28+2 -> 92 | Q28: Гофрокороб 324х222х134 Т-23 бел,Саянская,СПФ | R28: =G28*K28 -> 5.18694 | S28: =(H28*K28)+0.2 -> 5.96144 | T28: 78 | U28: 3 | V28: =T28/U28 -> 26 | W28: =X28-15 -> 464.99232 | X28: =IF(T28=0,0,S28*T28+15) -> 479.99232 | Y28: =T28*K28 -> 1170
A29: Фольга бытовая ЛЕНТА У8П-290х25 | B29: В пленке | C29: 11 | D29: 8 | E29: 290 | F29: 25 | G29: =IF(C29=14,13*D29*E29*2.71/1000000,C29*D29*E29*2.71/1000000) -> 0.0691592 | H29: =IF(AND(E29=290,F29=25),G29+0.026+0.001,IF(AND(E29=440,F29=25),G29+0.039+0.0013,IF(AND(E29=290,F29=33),G29+0.037+0.0013,IF(AND(E29=440,F29=33),G29+0.06+0.0018,IF(AND(E29=280,F29=25),G29+0.026+0.001,IF(AND(E29=280,F29=33),G29+0.037+0.0013)))))) -> 0.0961592 | I29: 305*32*32 | J29: 280 | K29: 25 | L29: =D29*60/J29 -> 1.7142857 | M29: =L29*K29 -> 42.857143 | N29: =K29*60/M29/K29 -> 1.4 | O29: =60/L29 -> 35 | P29: =M29+2 -> 44.857143 | Q29: Гофрокороб 324х222х134 Т-23 бел,СПФ | R29: =G29*K29 -> 1.72898 | S29: =(H29*K29)+0.2 -> 2.60398 | T29: 130 | U29: 5 | V29: =T29/U29 -> 26 | W29: =X29-15 -> 338.5174 | X29: =IF(T29=0,0,S29*T29+15) -> 353.5174 | Y29: =T29*K29 -> 3250
A30: Фольга HOMECLUB О10П-290х25 | B30: В пленке | C30: 14 | D30: 10 | E30: 290 | F30: 25 | G30: =IF(C30=14,13*D30*E30*2.71/1000000,C30*D30*E30*2.71/1000000) -> 0.102167 | H30: =IF(AND(E30=290,F30=25),G30+0.026+0.001,IF(AND(E30=290,F30=33),G30+0.037+0.0013,IF(AND(E30=440,F30=33),G30+0.06+0.0018,IF(AND(E30=280,F30=25),G30+0.026+0.001,IF(AND(E30=280,F30=33),G30+0.037+0.0013))))) -> 0.129167 | I30: 305*32*32 | J30: 350 | K30: 25 | L30: =D30*60/J30 -> 1.7142857 | M30: =L30*K30 -> 42.857143 | N30: =K30*60/M30/K30 -> 1.4 | O30: =60/L30 -> 35 | P30: =M30+2 -> 44.857143 | Q30: Гофрокороб 324х222х134 Т-23 бел,СПФ | R30: =G30*K30 -> 2.554175 | S30: =(H30*K30)+0.2 -> 3.429175 | T30: 130 | U30: 5 | V30: =T30/U30 -> 26 | W30: =X30-15 -> 445.79275 | X30: =IF(T30=0,0,S30*T30+15) -> 460.79275 | Y30: =T30*K30 -> 3250
A31: Фольга С60П-290х10, б/у | B31: Без упаковки | C31: 9 | D31: 60 | E31: 290 | F31: 33 | G31: =IF(C31=14,13*D31*E31*2.71/1000000,C31*D31*E31*2.71/1000000) -> 0.424386 | H31: =IF(AND(E31=290,F31=25),G31+0.026+0.001,IF(AND(E31=290,F31=33),G31+0.037+0.0013,IF(AND(E31=440,F31=33),G31+0.06+0.0018,IF(AND(E31=280,F31=25),G31+0.026+0.001,IF(AND(E31=280,F31=33),G31+0.037+0.0013))))) -> 0.462686 | I31: 305*50*50 | J31: 400 | K31: 10 | L31: =D31*60/J31 -> 9 | M31: =L31*K31 -> 90 | N31: =K31*60/M31/K31 -> 0.66666667 | O31: =60/L31 -> 6.6666667 | P31: =M31+2 -> 92 | Q31: Гофрокороб 324х222х134 Т-23 бел,СПФ | R31: =G31*K31 -> 4.24386 | S31: =(H31*K31)+0.2 -> 4.82686 | T31: 78 | U31: 3 | V31: =T31/U31 -> 26 | W31: =X31-15 -> 376.49508 | X31: =IF(T31=0,0,S31*T31+15) -> 391.49508 | Y31: =T31*K31 -> 780
A32: Фольга бытовая Kitchen Secrets С12П-290х49 | B32: В пленке | C32: 9 | D32: 12 | E32: 290 | F32: 25 | G32: =IF(C32=14,13*D32*E32*2.71/1000000,C32*D32*E32*2.71/1000000) -> 0.0848772 | H32: =IF(AND(E32=290,F32=25),G32+0.026+0.001,IF(AND(E32=290,F32=33),G32+0.037+0.0013,IF(AND(E32=440,F32=33),G32+0.06+0.0018,IF(AND(E32=280,F32=25),G32+0.026+0.001,IF(AND(E32=280,F32=33),G32+0.037+0.0013))))) -> 0.1118772 | I32: 305*32*32 | J32: 350 | K32: 49 | L32: =D32*60/J32 -> 2.0571429 | M32: =L32*K32 -> 100.8 | N32: =K32*60/M32/K32 -> 0.5952381 | O32: =60/L32 -> 29.166667 | P32: =M32+2 -> 102.8 | Q32: Гофрокороб 310х230х210 Т-23 бел,Kitchen secrets,СПФ | R32: =G32*K32 -> 4.1589828 | S32: =(H32*K32)+0.2 -> 5.6819828 | T32: 84 | U32: 7 | V32: =T32/U32 -> 12 | W32: =X32-15 -> 477.28656 | X32: =IF(T32=0,0,S32*T32+15) -> 492.28656 | Y32: =T32*K32 -> 4116
A33: Фольга Саянская У6П-290х35 | B33: В пленке | C33: 11 | D33: 6 | E33: 290 | F33: 25 | G33: =IF(C33=14,13*D33*E33*2.71/1000000,C33*D33*E33*2.71/1000000) -> 0.0518694 | H33: =IF(AND(E33=290,F33=25),G33+0.026+0.001,IF(AND(E33=290,F33=33),G33+0.037+0.0013,IF(AND(E33=440,F33=33),G33+0.06+0.0018,IF(AND(E33=280,F33=25),G33+0.026+0.001,IF(AND(E33=280,F33=33),G33+0.037+0.0013))))) -> 0.0788694 | I33: 305*32*32 | J33: 200 | K33: 35 | L33: =D33*60/J33 -> 1.8 | M33: =L33*K33 -> 63 | N33: =K33*60/M33/K33 -> 0.95238095 | O33: =60/L33 -> 33.333333 | P33: =M33+2 -> 65 | Q33: Гофрокороб 228х160х310 Т-23 бел с красн,Саянская,СПФ | R33: =G33*K33 -> 1.815429 | S33: =(H33*K33)+0.2 -> 2.960429 | T33: 96 | U33: 4 | V33: =T33/U33 -> 24 | W33: =X33-15 -> 284.20118 | X33: =IF(T33=0,0,S33*T33+15) -> 299.20118 | Y33: =T33*K33 -> 3360
A34: Фольга Саянская У10П-290х35 | B34: В пленке | C34: 11 | D34: 10 | E34: 290 | F34: 25 | G34: =IF(C34=14,13*D34*E34*2.71/1000000,C34*D34*E34*2.71/1000000) -> 0.086449 | H34: =IF(AND(E34=290,F34=25),G34+0.026+0.001,IF(AND(E34=290,F34=33),G34+0.037+0.0013,IF(AND(E34=440,F34=33),G34+0.06+0.0018,IF(AND(E34=280,F34=25),G34+0.026+0.001,IF(AND(E34=280,F34=33),G34+0.037+0.0013))))) -> 0.113449 | I34: 305*32*32 | J34: 350 | K34: 35 | L34: =D34*60/J34 -> 1.7142857 | M34: =L34*K34 -> 60 | N34: =K34*60/M34/K34 -> 1 | O34: =60/L34 -> 35 | P34: =M34+2 -> 62 | Q34: Гофрокороб 228х160х310 Т-23 бел с красн,Саянская,СПФ | R34: =G34*K34 -> 3.025715 | S34: =(H34*K34)+0.2 -> 4.170715 | T34: 96 | U34: 4 | V34: =T34/U34 -> 24 | W34: =X34-15 -> 400.38864 | X34: =IF(T34=0,0,S34*T34+15) -> 415.38864 | Y34: =T34*K34 -> 3360
A35: Фольга Саянская У25П-290х28 | B35: В пленке | C35: 11 | D35: 25 | E35: 290 | F35: 25 | G35: =IF(C35=14,13*D35*E35*2.71/1000000,C35*D35*E35*2.71/1000000) -> 0.2161225 | H35: =IF(AND(E35=290,F35=25),G35+0.026+0.001,IF(AND(E35=290,F35=33),G35+0.037+0.0013,IF(AND(E35=440,F35=33),G35+0.06+0.0018,IF(AND(E35=280,F35=25),G35+0.026+0.001,IF(AND(E35=280,F35=33),G35+0.037+0.0013))))) -> 0.2431225 | I35: 305*35*35 | J35: 400 | K35: 28 | L35: =D35*60/J35 -> 3.75 | M35: =L35*K35 -> 105 | N35: =K35*60/M35/K35 -> 0.57142857 | O35: =60/L35 -> 16 | P35: =M35+2 -> 107 | Q35: Гофрокороб 228х160х310 Т-23 бел с красн,Саянская,СПФ | R35: =G35*K35 -> 6.05143 | S35: =(H35*K35)+0.2 -> 7.00743 | T35: 120 | U35: 5 | V35: =T35/U35 -> 24 | W35: =X35-15 -> 840.8916 | X35: =IF(T35=0,0,S35*T35+15) -> 855.8916 | Y35: =T35*K35 -> 3360
A36: Фольга бытовая АШАН У30П-290х28 | B36: В пленке | C36: 11 | D36: 30 | E36: 290 | F36: 25 | G36: =IF(C36=14,13*D36*E36*2.71/1000000,C36*D36*E36*2.71/1000000) -> 0.259347 | H36: =IF(AND(E36=290,F36=25),G36+0.026+0.001,IF(AND(E36=290,F36=33),G36+0.037+0.0013,IF(AND(E36=440,F36=33),G36+0.06+0.0018,IF(AND(E36=280,F36=25),G36+0.026+0.001,IF(AND(E36=280,F36=33),G36+0.037+0.0013))))) -> 0.286347 | I36: 305*35*35 | J36: 400 | K36: 28 | L36: =D36*60/J36 -> 4.5 | M36: =L36*K36 -> 126 | N36: =K36*60/M36/K36 -> 0.47619048 | O36: =60/L36 -> 13.333333 | P36: =M36+2 -> 128 | Q36: Гофрокороб 228х160х310 Т-23 бел, Ашан, СПФ | R36: =G36*K36 -> 7.261716 | S36: =(H36*K36)+0.2 -> 8.217716 | T36: 72 | U36: 3 | V36: =T36/U36 -> 24 | W36: =X36-15 -> 591.67555 | X36: =IF(T36=0,0,S36*T36+15) -> 606.67555 | Y36: =T36*K36 -> 2016
A37: Фольга Саянская У50П-290х15 | B37: В пленке | C37: 11 | D37: 50 | E37: 290 | F37: 33 | G37: =IF(C37=14,13*D37*E37*2.71/1000000,C37*D37*E37*2.71/1000000) -> 0.432245 | H37: =IF(AND(E37=290,F37=25),G37+0.026+0.001,IF(AND(E37=290,F37=33),G37+0.037+0.0013,IF(AND(E37=440,F37=33),G37+0.06+0.0018,IF(AND(E37=280,F37=25),G37+0.026+0.001,IF(AND(E37=280,F37=33),G37+0.037+0.0013))))) -> 0.470545 | I37: 305*47*47 | J37: 400 | K37: 15 | L37: =D37*60/J37 -> 7.5 | M37: =L37*K37 -> 112.5 | N37: =K37*60/M37/K37 -> 0.53333333 | O37: =60/L37 -> 8 | P37: =M37+2 -> 114.5 | Q37: Гофрокороб 228х160х310 Т-23 бел с красн,Саянская,СПФ | R37: =G37*K37 -> 6.483675 | S37: =(H37*K37)+0.2 -> 7.258175 | T37: 72 | U37: 3 | V37: =T37/U37 -> 24 | W37: =X37-15 -> 522.5886 | X37: =IF(T37=0,0,S37*T37+15) -> 537.5886 | Y37: =T37*K37 -> 1080
